Workbook
Name SegmentaçãodeDados_Mês: #N/A

Sheet Planilha8
D1: nova | G1: old | I1: vr.
B2: 1000000 | E2: 1000000
B3: 46143 | E3: 46143
C4: Adj. Ebitda After Capex | F4: Adj. Ebitda After Capex
C9: Actual | F9: Actual
B11: Consolidado nstech | C11: 21.963357 | E11: Consolidado nstech | F11: 22.053523 | H11: =F11-C11 -> 0.09016632 | I11: =H11*10^6 -> 90166.32 | J11: =H11/C11 -> 0.0041053069 | L11: Fechamento Mai26 - Mapeamento de alterações
B13: Consolidado PSL | C13: 19.283281 | E13: Consolidado PSL | F13: 19.359549 | H13: =F13-C13 -> 0.07626753 | I13: =H13*10^6 -> 76267.53 | L13: Total Resultado | N13: =SUM(N20,N27) -> -90.164 | O13: 0.0041053069
B14: Torre TMS | C14: 9.0247915 | E14: Torre TMS | F14: 9.1010591 | H14: =F14-C14 -> 0.07626753 | I14: =H14*10^6 -> 76267.53
B15: Torre ICP Pequeno e Micro | C15: 7.1296428 | E15: Torre ICP Pequeno e Micro | F15: 7.1296428 | H15: =F15-C15 -> 0 | I15: =H15*10^6 -> 0 | M15: Empresa | N15: Valor | O15: Motivo
B16: Bsoft | C16: 5.3466884 | E16: Bsoft | F16: 5.3466884 | H16: =F16-C16 -> 0 | I16: =H16*10^6 -> 0 | L16: ATSLog
B17: Datamex | C17: 0.46905115 | E17: Datamex | F17: 0.46905115 | H17: =F17-C17 -> 0 | I17: =H17*10^6 -> 0 | M17: Outros | N17: -31.41 | O17: Conta de despesa, não veio no BI
B18: Hivecloud | C18: 1.2579829 | E18: Hivecloud | F18: 1.2579829 | H18: =F18-C18 -> 0 | I18: =H18*10^6 -> 0 | M18: Jornada | N18: -44.857 | O18: Conta de despesa, não veio no BI
B19: Otimizy | C19: 0.055920294 | E19: Otimizy | F19: 0.055920294 | H19: =F19-C19 -> 0 | I19: =H19*10^6 -> 0
B20: Torre ICP Médio e Grande | C20: 1.160067 | E20: Torre ICP Médio e Grande | F20: 1.2363345 | H20: =F20-C20 -> 0.07626753 | I20: =H20*10^6 -> 76267.53 | L20: Total PSL | N20: =SUM(N17:N18) -> -76.267
B21: TMS MG | C21: -1.7567802 | E21: TMS MG | F21: -1.7253702 | H21: =F21-C21 -> 0.03141001 | I21: =H21*10^6 -> 31410.01
B22: KMM MG | C22: -2.0497984 | E22: KMM MG | F22: -2.0497984 | H22: =F22-C22 -> 0 | I22: =H22*10^6 -> 0
B23: ATSLog Outros | C23: 0.19805047 | E23: ATSLog Outros | F23: 0.22946048 | H23: =F23-C23 -> 0.03141001 | I23: =H23*10^6 -> 31410.01 | L23: BRK | N23: -5.242 | O23: Conta duplicada em "Others Income and Expenses"
B24: Praxio - Avacorp | C24: -0.080853175 | E24: Praxio - Avacorp | F24: -0.080853175 | H24: =F24-C24 -> 0 | I24: =H24*10^6 -> 0 | L24: Onisys | N24: -8.655 | O24: Conta duplicada em "Others Income and Expenses"
B25: Praxio - Globus | C25: 0.1758209 | E25: Praxio - Globus | F25: 0.1758209 | H25: =F25-C25 -> 0 | I25: =H25*10^6 -> 0
B26: Atua | C26: 2.3656454 | E26: Atua | F26: 2.3656454 | H26: =F26-C26 -> 0 | I26: =H26*10^6 -> 0 | L26: Total BU Embarcador
B27: ATSLog Jornada | C27: 0.40740325 | E27: ATSLog Jornada | F27: 0.45226077 | H27: =F27-C27 -> 0.04485752 | I27: =H27*10^6 -> 44857.52 | N27: =SUM(N23:N24) -> -13.897
B28: NSKote | C28: 0.14379849 | E28: NSKote | F28: 0.14379849 | H28: =F28-C28 -> 0 | I28: =H28*10^6 -> 0
B29: Signa | C29: 0.73508178 | E29: Signa | F29: 0.73508178 | H29: =F29-C29 -> 0 | I29: =H29*10^6 -> 0
B30: Fintech | C30: 2.9369959 | E30: Fintech | F30: 2.9369959 | H30: =F30-C30 -> 0 | I30: =H30*10^6 -> 0
B31: e-frete | C31: 1.3080537 | E31: e-frete | F31: 1.3080537 | H31: =F31-C31 -> 0 | I31: =H31*10^6 -> 0
B32: e-frete Meio Pagamento | C32: 1.3721186 | E32: e-frete Meio Pagamento | F32: 1.3721186 | H32: =F32-C32 -> 0 | I32: =H32*10^6 -> 0
B33: e-frete nsflow | C33: -0.06667544 | E33: e-frete nsflow | F33: -0.06667544 | H33: =F33-C33 -> 0 | I33: =H33*10^6 -> 0
B34: Torre Fintech - PSL | C34: 0.00261056 | E34: Torre Fintech - PSL | F34: 0.00261056 | H34: =F34-C34 -> 0 | I34: =H34*10^6 -> 0
B35: Gasola | C35: 0.54752537 | E35: Gasola | F35: 0.54752537 | H35: =F35-C35 -> 0 | I35: =H35*10^6 -> 0
B36: Pedágio | C36: 1.0814168 | E36: Pedágio | F36: 1.0814168 | H36: =F36-C36 -> 0 | I36: =H36*10^6 -> 0
B37: Digitalcomm | C37: 0.6036868 | E37: Digitalcomm | F37: 0.6036868 | H37: =F37-C37 -> 0 | I37: =H37*10^6 -> 0
B38: e-frete Pedágio | C38: 0.14197763 | E38: e-frete Pedágio | F38: 0.14197763 | H38: =F38-C38 -> 0 | I38: =H38*10^6 -> 0
B39: Qualp | C39: 0.33575241 | E39: Qualp | F39: 0.33575241 | H39: =F39-C39 -> 0 | I39: =H39*10^6 -> 0
... B49: BU PSL CS | C49: -0.1215734 | E49: BU PSL CS | F49: -0.1215734 | H49: =F49-C49 -> 0 | I49: =H49*10^6 -> 0
I50: =H50*10^6 -> 0
B51: Consolidado Embarcador | C51: 12.757321 | E51: Consolidado Embarcador | F51: 12.77122 | H51: =F51-C51 -> 0.01389879 | I51: =H51*10^6 -> 13898.79
B52: Torre VGR | C52: 13.582673 | E52: Torre VGR | F52: 13.596572 | H52: =F52-C52 -> 0.01389879 | I52: =H52*10^6 -> 13898.79
B53: Opentech | C53: 4.6633703 | E53: Opentech | F53: 4.6633703 | H53: =F53-C53 -> 0 | I53: =H53*10^6 -> 0
B54: BRK | C54: 6.256908 | E54: BRK | F54: 6.262151 | H54: =F54-C54 -> 0.00524299 | I54: =H54*10^6 -> 5242.99
B55: LogRisk | C55: 1.3676425 | E55: LogRisk | F55: 1.3676425 | H55: =F55-C55 -> 0 | I55: =H55*10^6 -> 0
...

Sheet Empillhado
F6: Jan | G6: Feb | H6: Mar | I6: Apr | J6: May | K6: YTD | L6: Jun | M6: Jul | N6: Aug | O6: Set | P6: Oct | Q6: Nov | R6: Dec | S6: Full Year | U6: 1Q | V6: 2Q | W6: 3Q | X6: 4Q | Y6: Full Year
C10: Net Revenue Contábil
D11: Actual | E11: 2024 | F11: 69974.548 | G11: 69844.884 | H11: 72994.185 | I11: 75032.306 | J11: 77044.186 | K11: =SUM(F11:J11) -> 364890.11 | L11: 79737.524 | M11: 82235.21 | N11: 82395.173 | O11: 82409.301 | P11: 90317.968 | Q11: 84507.935 | R11: 85975.636 | S11: =SUM(K11:R11) -> 952468.86 | U11: =SUM(F11:G11,H11) -> 212813.62 | V11: =SUM(I11,J11,L11) -> 231814.02 | W11: =SUM(M11:O11) -> 247039.68 | X11: =SUM(P11:R11) -> 260801.54 | Y11: =SUM(U11:X11) -> 952468.86
D12: Actual | E12: 2025 | F12: 91352.84 | G12: 90612.467 | H12: 91858.182 | I12: 92547.036 | J12: 95185.544 | K12: =SUM(F12:J12) -> 461556.07 | L12: 90717.613 | M12: 90078.395 | N12: 98389.379 | O12: 101231.72 | P12: 109542.93 | Q12: 103163.04 | R12: 101055.22 | S12: =SUM(K12:R12) -> 1155734.4 | U12: =SUM(F12:G12,H12) -> 273823.49 | V12: =SUM(I12,J12,L12) -> 278450.19 | W12: =SUM(M12:O12) -> 289699.5 | X12: =SUM(P12:R12) -> 313761.19 | Y12: =SUM(U12:X12) -> 1155734.4
D13: Budget | E13: 2026 | F13: 104452.96 | G13: 104590.28 | H13: 108978.13 | I13: 110603.63 | J13: 113070.77 | K13: =SUM(F13:J13) -> 541695.77 | L13: 118169.73 | M13: 120040.07 | N13: 121218.11 | O13: 135105.5 | P13: 125420.36 | Q13: 126008.46 | R13: 126627.93 | S13: =SUM(K13:R13) -> 1414285.9 | U13: =SUM(F13:G13,H13) -> 318021.37 | V13: =SUM(I13,J13,L13) -> 341844.13 | W13: =SUM(M13:O13) -> 376363.68 | X13: =SUM(P13:R13) -> 378056.75 | Y13: =SUM(U13:X13) -> 1414285.9
D14: Forecast | E14: 2026 | F14: 106599.38 | G14: 104831.3 | H14: 107263.69 | I14: 111037.74 | J14: 111619.43 | K14: =SUM(F14:J14) -> 541351.54 | L14: 115609.78 | M14: 117485.01 | N14: 119733.09 | O14: 133736.62 | P14: 124435.7 | Q14: 125402.45 | R14: 126468.54 | S14: =SUM(K14:R14) -> 1404222.7 | U14: =SUM(F14:G14,H14) -> 318694.37 | V14: =SUM(I14,J14,L14) -> 338266.94 | W14: =SUM(M14:O14) -> 370954.72 | X14: =SUM(P14:R14) -> 376306.7 | Y14: =SUM(U14:X14) -> 1404222.7
D15: Actual | E15: 2026 | F15: 106599.38 | G15: 104831.3 | H15: 107263.69 | I15: 111037.74 | J15: 113734.67 | K15: =SUM(F15:J15) -> 543466.78 | L15: =L14 -> 115609.78 | M15: =M14 -> 117485.01 | N15: =N14 -> 119733.09 | O15: =O14 -> 133736.62 | P15: =P14 -> 124435.7 | Q15: =Q14 -> 125402.45 | R15: =R14 -> 126468.54 | S15: =SUM(K15:R15) -> 1406338 | U15: =SUM(F15:G15,H15) -> 318694.37 | V15: =SUM(I15,J15,L15) -> 340382.19 | W15: =SUM(M15:O15) -> 370954.72 | X15: =SUM(P15:R15) -> 376306.7 | Y15: =SUM(U15:X15) -> 1406338
D16: % 25 (Act) x 24 (Act) | F16: =F12/F11-1 -> 0.30551525 | G16: =G12/G11-1 -> 0.29733865 | H16: =H12/H11-1 -> 0.25843149 | I16: =I12/I11-1 -> 0.23342918 | J16: =J12/J11-1 -> 0.23546692 | K16: =K12/K11-1 -> 0.264918 | L16: =L12/L11-1 -> 0.13770291 | M16: =M12/M11-1 -> 0.095375015 | ... S16: =S12/S11-1 -> 0.21340908 | U16: =U12/U11-1 -> 0.28668218 | V16: =V12/V11-1 -> 0.20117928 | W16: =W12/W11-1 -> 0.17268404 | X16: =X12/X11-1 -> 0.20306493 | Y16: =Y12/Y11-1 -> 0.21340908
D17: % 26 (Act) x 25 (Act) | F17: =F15/F12-1 -> 0.16689731 | G17: =G15/G12-1 -> 0.15691912 | H17: =H15/H12-1 -> 0.16770972 | I17: =I15/I12-1 -> 0.1997979 | J17: =J15/J12-1 -> 0.19487333 | K17: =K15/K12-1 -> 0.17746643 | L17: =L15/L12-1 -> 0.27439174 | M17: =M15/M12-1 -> 0.30425293 | ... S17: =S15/S12-1 -> 0.21683496 | U17: =U15/U12-1 -> 0.16386791 | V17: =V15/V12-1 -> 0.22241677 | W17: =W15/W12-1 -> 0.28048108 | X17: =X15/X12-1 -> 0.19934113 | Y17: =Y15/Y12-1 -> 0.21683496
D18: % 26 (Act) x 26 (Bgt) | F18: =F15/F13-1 -> 0.020549171 | G18: =G15/G13-1 -> 0.0023043876 | H18: =H15/H13-1 -> -0.015731968 | I18: =I15/I13-1 -> 0.0039249233 | J18: =J15/J13-1 -> 0.0058715277 | K18: =K15/K13-1 -> 0.0032693752 | L18: =L15/L13-1 -> -0.021663336 | M18: =M15/M13-1 -> -0.021285069 | ... S18: =S15/S13-1 -> -0.0056197594 | U18: =U15/U13-1 -> 0.0021162031 | V18: =V15/V13-1 -> -0.0042766321 | W18: =W15/W13-1 -> -0.014371608 | X18: =X15/X13-1 -> -0.004629071 | Y18: =Y15/Y13-1 -> -0.0056197594
D19: % 26 (Act) x 26 (Rfc) | F19: =F15/F14-1 -> 0 | G19: =G15/G14-1 -> 0 | H19: =H15/H14-1 -> 0 | I19: =I15/I14-1 -> 0 | J19: =J15/J14-1 -> 0.018950473 | K19: =K15/K14-1 -> 0.0039073333 | L19: =L15/L14-1 -> 0 | M19: =M15/M14-1 -> 0 | ... S19: =S15/S14-1 -> 0.0015063429 | U19: =U15/U14-1 -> 0 | V19: =V15/V14-1 -> 0.0062531706 | W19: =W15/W14-1 -> 0 | X19: =X15/X14-1 -> 0 | Y19: =Y15/Y14-1 -> 0.0015063429
C21: Net Revenue - Contábil Ajustado 1) Ajustando provisão de receita na competência de origem 2) Considera eliminação intercompany de 2024 (contabilmente não existe)
D22: Actual | E22: 2024 | F22: 69593.317 | G22: 69370.873 | H22: 72615.298 | I22: 74529.2 | J22: 76509.687 | K22: =SUM(F22:J22) -> 362618.38 | L22: 79207.305 | M22: 81672.212 | N22: 81694.305 | O22: 81468.623 | P22: 89419.544 | Q22: 83320.997 | R22: 82432.92 | S22: =SUM(K22:R22) -> 941834.28 | U22: =SUM(F22:G22,H22) -> 211579.49 | V22: =SUM(I22,J22,L22) -> 230246.19 | W22: =SUM(M22:O22) -> 244835.14 | X22: =SUM(P22:R22) -> 255173.46 | Y22: =SUM(U22:X22) -> 941834.28
D23: Actual | E23: 2025 | F23: 91352.84 | G23: 90612.467 | H23: 91858.182 | I23: 92547.036 | J23: 95185.544 | K23: =SUM(F23:J23) -> 461556.07 | L23: 93052.097 | M23: 91360.204 | N23: 98389.379 | O23: 101231.72 | P23: 109542.93 | Q23: 103264.41 | R23: 101319.27 | S23: =SUM(K23:R23) -> 1159716.1 | U23: =SUM(F23:G23,H23) -> 273823.49 | V23: =SUM(I23,J23,L23) -> 280784.68 | W23: =SUM(M23:O23) -> 290981.31 | X23: =SUM(P23:R23) -> 314126.62 | Y23: =SUM(U23:X23) -> 1159716.1
D24: Budget | E24: 2026 | F24: =F13 -> 104452.96 | G24: =G13 -> 104590.28 | H24: =H13 -> 108978.13 | I24: =I13 -> 110603.63 | J24: =J13 -> 113070.77 | K24: =SUM(F24:J24) -> 541695.77 | L24: =L13 -> 118169.73 | M24: =M13 -> 120040.07 | N24: =N13 -> 121218.11 | O24: =O13 -> 135105.5 | P24: =P13 -> 125420.36 | Q24: =Q13 -> 126008.46 | R24: =R13 -> 126627.93 | S24: =SUM(K24:R24) -> 1414285.9 | U24: =SUM(F24:G24,H24) -> 318021.37 | V24: =SUM(I24,J24,L24) -> 341844.13 | W24: =SUM(M24:O24) -> 376363.68 | X24: =SUM(P24:R24) -> 378056.75 | Y24: =SUM(U24:X24) -> 1414285.9
D25: Forecast | E25: 2026 | F25: 106599.38 | G25: 104831.3 | H25: 107263.69 | I25: 111037.74 | J25: 111619.43 | K25: =SUM(F25:J25) -> 541351.54 | L25: 115609.78 | M25: 117485.01 | N25: 119733.09 | O25: 133736.62 | P25: 124435.7 | Q25: 125402.45 | R25: 126468.54 | S25: =SUM(K25:R25) -> 1404222.7 | U25: =SUM(F25:G25,H25) -> 318694.37 | V25: =SUM(I25,J25,L25) -> 338266.94 | W25: =SUM(M25:O25) -> 370954.72 | X25: =SUM(P25:R25) -> 376306.7 | Y25: =SUM(U25:X25) -> 1404222.7
D26: Actual | E26: 2026 | F26: =F15 -> 106599.38 | G26: =G15 -> 104831.3 | H26: =H15 -> 107263.69 | I26: 111037.74 | J26: 113734.67 | K26: =SUM(F26:J26) -> 543466.78 | L26: =L25 -> 115609.78 | M26: =M25 -> 117485.01 | N26: =N25 -> 119733.09 | O26: =O25 -> 133736.62 | P26: =P25 -> 124435.7 | Q26: =Q25 -> 125402.45 | R26: =R25 -> 126468.54 | S26: =SUM(K26:R26) -> 1406338 | U26: =SUM(F26:G26,H26) -> 318694.37 | V26: =SUM(I26,J26,L26) -> 340382.19 | W26: =SUM(M26:O26) -> 370954.72 | X26: =SUM(P26:R26) -> 376306.7 | Y26: =SUM(U26:X26) -> 1406338
D27: % 25 (Act) x 24 (Act) | F27: =F23/F22-1 -> 0.31266684 | G27: =G23/G22-1 -> 0.30620336 | H27: =H23/H22-1 -> 0.26499765 | I27: =I23/I22-1 -> 0.24175539 | J27: =J23/J22-1 -> 0.24409794 | K27: =K23/K22-1 -> 0.27284247 | L27: =L23/L22-1 -> 0.17479185 | M27: =M23/M22-1 -> 0.11862043 | ... S27: =S23/S22-1 -> 0.23133773 | U27: =U23/U22-1 -> 0.29418731 | V27: =V23/V22-1 -> 0.21949759 | W27: =W23/W22-1 -> 0.18847852 | X27: =X23/X22-1 -> 0.23103168 | Y27: =Y23/Y22-1 -> 0.23133773
D28: % 26 (Act) x 25 (Act) | F28: =F26/F23-1 -> 0.16689731 | G28: =G26/G23-1 -> 0.15691912 | H28: =H26/H23-1 -> 0.16770972 | I28: =I26/I23-1 -> 0.1997979 | J28: =J26/J23-1 -> 0.19487333 | K28: =K26/K23-1 -> 0.17746643 | L28: =L26/L23-1 -> 0.24241991 | M28: =M26/M23-1 -> 0.28595389 | ... S28: =S26/S23-1 -> 0.21265713 | U28: =U26/U23-1 -> 0.16386791 | V28: =V26/V23-1 -> 0.21225342 | W28: =W26/W23-1 -> 0.2748404 | X28: =X26/X23-1 -> 0.19794592 | Y28: =Y26/Y23-1 -> 0.21265713
D29: % 26 (Act) x 26 (Bgt) | F29: =F26/F24-1 -> 0.020549171 | G29: =G26/G24-1 -> 0.0023043876 | H29: =H26/H24-1 -> -0.015731968 | I29: =I26/I24-1 -> 0.0039249233 | J29: =J26/J24-1 -> 0.0058715277 | K29: =K26/K24-1 -> 0.0032693752 | L29: =L26/L24-1 -> -0.021663336 | M29: =M26/M24-1 -> -0.021285069 | ... S29: =S26/S24-1 -> -0.0056197594 | U29: =U26/U24-1 -> 0.0021162031 | V29: =V26/V24-1 -> -0.0042766321 | W29: =W26/W24-1 -> -0.014371608 | X29: =X26/X24-1 -> -0.004629071 | Y29: =Y26/Y24-1 -> -0.0056197594
D30: % 26 (Act) x 26 (Rfc) | F30: =F26/F25-1 -> 0 | G30: =G26/G25-1 -> 0 | H30: =H26/H25-1 -> 0 | I30: =I26/I25-1 -> 0 | J30: =J26/J25-1 -> 0.018950473 | K30: =K26/K25-1 -> 0.0039073333 | L30: =L26/L25-1 -> 0 | M30: =M26/M25-1 -> 0 | ... S30: =S26/S25-1 -> 0.0015063429 | U30: =U26/U25-1 -> 0 | V30: =V26/V25-1 -> 0.0062531706 | W30: =W26/W25-1 -> 0 | X30: =X26/X25-1 -> 0 | Y30: =Y26/Y25-1 -> 0.0015063429
C32: Net Revenue - Orgânico Ajustado
D33: Actual | E33: 2024 | F33: 74899.301 | G33: 74515.061 | H33: 78804.55 | I33: 80191.125 | J33: 81204.579 | K33: =SUM(F33:J33) -> 389614.61 | L33: 83717.445 | M33: 86214.598 | N33: 86675.377 | O33: 87309.391 | P33: 94903.091 | Q33: 89241.924 | R33: 84295.323 | S33: =SUM(K33:R33) -> 1001971.8 | U33: =SUM(F33:G33,H33) -> 228218.91 | V33: =SUM(I33,J33,L33) -> 245113.15 | W33: =SUM(M33:O33) -> 260199.37 | X33: =SUM(P33:R33) -> 268440.34 | Y33: =SUM(U33:X33) -> 1001971.8
D34: Actual | E34: 2025 | F34: =92754.4230211031 -> 92754.423 | G34: 91911.149 | H34: 93355.651 | I34: 94307.257 | J34: 96658.286 | K34: =SUM(F34:J34) -> 468986.77 | L34: 95038.412 | M34: 92539.742 | N34: 99290.606 | O34: 102168.91 | P34: 110453.8 | Q34: 103264.41 | R34: 101319.27 | S34: =SUM(K34:R34) -> 1173061.9 | U34: =SUM(F34:G34,H34) -> 278021.22 | V34: =SUM(I34,J34,L34) -> 286003.96 | W34: =SUM(M34:O34) -> 293999.26 | X34: =SUM(P34:R34) -> 315037.48 | Y34: =SUM(U34:X34) -> 1173061.9
D35: Budget | E35: 2026 | F35: =F24 -> 104452.96 | G35: =G24 -> 104590.28 | H35: =H24 -> 108978.13 | I35: =I24 -> 110603.63 | J35: =J24 -> 113070.77 | K35: =SUM(F35:J35) -> 541695.77 | L35: =L24 -> 118169.73 | M35: =M24 -> 120040.07 | N35: =N24 -> 121218.11 | O35: =O24 -> 135105.5 | P35: =P24 -> 125420.36 | Q35: =Q24 -> 126008.46 | R35: =R24 -> 126627.93 | S35: =SUM(K35:R35) -> 1414285.9 | U35: =SUM(F35:G35,H35) -> 318021.37 | V35: =SUM(I35,J35,L35) -> 341844.13 | W35: =SUM(M35:O35) -> 376363.68 | X35: =SUM(P35:R35) -> 378056.75 | Y35: =SUM(U35:X35) -> 1414285.9
D36: Forecast | E36: 2026 | F36: 106599.38 | G36: 104831.3 | H36: 107263.69 | I36: 111037.74 | J36: 111619.43 | K36: =SUM(F36:J36) -> 541351.54 | L36: 115609.78 | M36: 117485.01 | N36: 119733.09 | O36: 133736.62 | P36: 124435.7 | Q36: 125402.45 | R36: 126468.54 | S36: =SUM(K36:R36) -> 1404222.7 | U36: =SUM(F36:G36,H36) -> 318694.37 | V36: =SUM(I36,J36,L36) -> 338266.94 | W36: =SUM(M36:O36) -> 370954.72 | X36: =SUM(P36:R36) -> 376306.7 | Y36: =SUM(U36:X36) -> 1404222.7
D37: Actual | E37: 2026 | F37: =F15 -> 106599.38 | G37: =G26 -> 104831.3 | H37: =H26 -> 107263.69 | I37: =I26 -> 111037.74 | J37: =J26 -> 113734.67 | K37: =SUM(F37:J37) -> 543466.78 | L37: =L36 -> 115609.78 | M37: =M36 -> 117485.01 | N37: =N36 -> 119733.09 | O37: =O36 -> 133736.62 | P37: =P36 -> 124435.7 | Q37: =Q36 -> 125402.45 | R37: =R36 -> 126468.54 | S37: =SUM(K37:R37) -> 1406338 | U37: =SUM(F37:G37,H37) -> 318694.37 | V37: =SUM(I37,J37,L37) -> 340382.19 | W37: =SUM(M37:O37) -> 370954.72 | X37: =SUM(P37:R37) -> 376306.7 | Y37: =SUM(U37:X37) -> 1406338
D38: % 25 (Act) x 24 (Act) | F38: =F34/F33-1 -> 0.23838837 | G38: =G34/G33-1 -> 0.23345735 | H38: =H34/H33-1 -> 0.18464798 | I38: =I34/I33-1 -> 0.17603111 | J38: =J34/J33-1 -> 0.19030586 | K38: =K34/K33-1 -> 0.20371965 | L38: =L34/L33-1 -> 0.13522829 | M38: =M34/M33-1 -> 0.073365118 | ... S38: =S34/S33-1 -> 0.17075347 | U38: =U34/U33-1 -> 0.21822167 | V38: =V34/V33-1 -> 0.16682421 | W38: =W34/W33-1 -> 0.12989999 | X38: =X34/X33-1 -> 0.17358473 | Y38: =Y34/Y33-1 -> 0.17075347
D39: % 26 (Act) x 25 (Act) | F39: =F37/F34-1 -> 0.14926469 | G39: =G37/G34-1 -> 0.14057213 | H39: =H37/H34-1 -> 0.1489791 | I39: =I37/I34-1 -> 0.17740397 | J39: =J37/J34-1 -> 0.17666754 | K39: =K37/K34-1 -> 0.15881048 | L39: =L37/L34-1 -> 0.21645317 | M39: =M37/M34-1 -> 0.26956275 | ... S39: =S37/S34-1 -> 0.19886082 | U39: =U37/U34-1 -> 0.14629512 | V39: =V37/V34-1 -> 0.19013104 | W39: =W37/W34-1 -> 0.26175394 | X39: =X37/X34-1 -> 0.19448231 | Y39: =Y37/Y34-1 -> 0.19886082
D40: % 26 (Act) x 26 (Bgt) | F40: =F37/F35-1 -> 0.020549171 | G40: =G37/G35-1 -> 0.0023043876 | H40: =H37/H35-1 -> -0.015731968 | I40: =I37/I35-1 -> 0.0039249233 | J40: =J37/J35-1 -> 0.0058715277 | K40: =K37/K35-1 -> 0.0032693752 | L40: =L37/L35-1 -> -0.021663336 | M40: =M37/M35-1 -> -0.021285069 | ... S40: =S37/S35-1 -> -0.0056197594 | U40: =U37/U35-1 -> 0.0021162031 | V40: =V37/V35-1 -> -0.0042766321 | W40: =W37/W35-1 -> -0.014371608 | X40: =X37/X35-1 -> -0.004629071 | Y40: =Y37/Y35-1 -> -0.0056197594
D41: % 26 (Act) x 26 (Rfc) | F41: =F37/F36-1 -> 0 | G41: =G37/G36-1 -> 0 | H41: =H37/H36-1 -> 0 | I41: =I37/I36-1 -> 0 | J41: =J37/J36-1 -> 0.018950473 | K41: =K37/K36-1 -> 0.0039073333 | L41: =L37/L36-1 -> 0 | M41: =M37/M36-1 -> 0 | ... S41: =S37/S36-1 -> 0.0015063429 | U41: =U37/U36-1 -> 0 | V41: =V37/V36-1 -> 0.0062531706 | W41: =W37/W36-1 -> 0 | X41: =X37/X36-1 -> 0 | Y41: =Y37/Y36-1 -> 0.0015063429
C43: Adjusted EBITDA
D44: Actual | E44: 2024 | F44: 16979.872 | G44: 12830.786 | H44: 15086.515 | I44: 14900.988 | J44: 16517.669 | K44: =SUM(F44:J44) -> 76315.83 | L44: 21271.893 | M44: 19772.247 | N44: 19885.52 | O44: 23989.438 | P44: 22055.599 | Q44: 16363.687 | R44: 11006.227 | S44: =SUM(K44:R44) -> 210660.44 | U44: =SUM(F44:G44,H44) -> 44897.173 | V44: =SUM(I44,J44,L44) -> 52690.55 | W44: =SUM(M44:O44) -> 63647.205 | X44: =SUM(P44:R44) -> 49425.513 | Y44: =SUM(U44:X44) -> 210660.44
D45: Actual | E45: 2025 | F45: 19364.982 | G45: 17234.531 | H45: 18910.161 | I45: 20957.21 | J45: 22718.949 | K45: =SUM(F45:J45) -> 99185.833 | L45: 18698.385 | M45: 11439.798 | N45: 19030.364 | O45: 23163.767 | P45: 33582.398 | Q45: 34781.384 | R45: =24592.3715281149-1576.205 -> 23016.167 | S45: =SUM(K45:R45) -> 262898.1 | U45: =SUM(F45:G45,H45) -> 55509.674 | V45: =SUM(I45,J45,L45) -> 62374.545 | W45: =SUM(M45:O45) -> 53633.929 | X45: =SUM(P45:R45) -> 91379.948 | Y45: =SUM(U45:X45) -> 262898.1
D46: Budget | E46: 2026 | F46: =F64-[1]Empillhado!F154 -> 16586.961 | G46: =G64-[1]Empillhado!G154 -> 15577.279 | H46: =H64-[1]Empillhado!H154 -> 15298.111 | I46: =I64-[1]Empillhado!I154 -> 15977.409 | J46: =J64-[1]Empillhado!J154 -> 17160.363 | K46: =SUM(F46:J46) -> 80600.123 | L46: =L64-[1]Empillhado!L154 -> 17877.244 | M46: =M64-[1]Empillhado!M154 -> 21613.485 | N46: =N64-[1]Empillhado!N154 -> 21353.103 | O46: =O64-[1]Empillhado!O154 -> 28960.706 | P46: =P64-[1]Empillhado!P154 -> 26936.868 | Q46: =Q64-[1]Empillhado!Q154 -> 27232.027 | R46: =R64-[1]Empillhado!R154 -> 25064.366 | S46: =SUM(K46:R46) -> 249637.92 | U46: =SUM(F46:G46,H46) -> 47462.352 | V46: =SUM(I46,J46,L46) -> 51015.015 | W46: =SUM(M46:O46) -> 71927.294 | X46: =SUM(P46:R46) -> 79233.261 | Y46: =SUM(U46:X46) -> 249637.92
D47: Forecast | E47: 2026 | F47: =F48 -> 22496.568 | G47: =G48 -> 21677.649 | H47: =H48 -> 21418.495 | I47: =I48 -> 28184.804 | J47: =J65-[1]Empillhado!J155 -> 17728.989 | K47: =SUM(F47:J47) -> 111506.5 | L47: =L65-[1]Empillhado!L155 -> 17099.983 | M47: =M65-[1]Empillhado!M155 -> 19481.631 | N47: =N65-[1]Empillhado!N155 -> 20150.334 | O47: =O65-[1]Empillhado!O155 -> 27841.228 | P47: =P65-[1]Empillhado!P155 -> 26828.845 | Q47: =Q65-[1]Empillhado!Q155 -> 27132.086 | R47: =R65-[1]Empillhado!R155 -> 27181.863 | S47: =SUM(K47:R47) -> 277222.48 | U47: =SUM(F47:G47,H47) -> 65592.712 | V47: =SUM(I47,J47,L47) -> 63013.776 | W47: =SUM(M47:O47) -> 67473.193 | X47: =SUM(P47:R47) -> 81142.795 | Y47: =SUM(U47:X47) -> 277222.48
D48: Actual | E48: 2026 | F48: 22496.568 | G48: 21677.649 | H48: 21418.495 | I48: 28184.804 | J48: 34075.192 | K48: =SUM(F48:J48) -> 127852.71 | L48: =L47 -> 17099.983 | M48: =M47 -> 19481.631 | N48: =N47 -> 20150.334 | O48: =O47 -> 27841.228 | P48: =P47 -> 26828.845 | Q48: =Q47 -> 27132.086 | R48: =R47 -> 27181.863 | S48: =SUM(K48:R48) -> 293568.68 | U48: =SUM(F48:G48,H48) -> 65592.712 | V48: =SUM(I48,J48,L48) -> 79359.979 | W48: =SUM(M48:O48) -> 67473.193 | X48: =SUM(P48:R48) -> 81142.795 | Y48: =SUM(U48:X48) -> 293568.68
D49: % 25 (Act) x 24 (Act) | F49: =F45/F44-1 -> 0.14046687 | G49: =G45/G44-1 -> 0.34321715 | H49: =H45/H44-1 -> 0.25344791 | I49: =I45/I44-1 -> 0.40643088 | J49: =J45/J44-1 -> 0.37543315 | K49: =K45/K44-1 -> 0.29967574 | L49: =L45/L44-1 -> -0.12098159 | M49: =M45/M44-1 -> -0.42142147 | ... S49: =S45/S44-1 -> 0.24797088 | U49: =U45/U44-1 -> 0.23637347 | V49: =V45/V44-1 -> 0.18378997 | W49: =W45/W44-1 -> -0.15732468 | X49: =X45/X44-1 -> 0.84884168 | Y49: =Y45/Y44-1 -> 0.24797088
D50: % 26 (Act) x 25 (Act) | F50: =F48/F45-1 -> 0.16171389 | G50: =G48/G45-1 -> 0.25780324 | H50: =H48/H45-1 -> 0.13264475 | I50: =I48/I45-1 -> 0.34487383 | J50: =J48/J45-1 -> 0.49985776 | K50: =K48/K45-1 -> 0.28902187 | L50: =L48/L45-1 -> -0.085483424 | M50: =M48/M45-1 -> 0.7029699 | ... S50: =S48/S45-1 -> 0.11666339 | U50: =U48/U45-1 -> 0.1816447 | V50: =V48/V45-1 -> 0.27231356 | W50: =W48/W45-1 -> 0.25803187 | X50: =X48/X45-1 -> -0.11202845 | Y50: =Y48/Y45-1 -> 0.11666339
D51: % 26 (Act) x 26 (Bgt) | F51: =F48/F46-1 -> 0.35628025 | G51: =G48/G46-1 -> 0.39161974 | H51: =H48/H46-1 -> 0.40007445 | I51: =I48/I46-1 -> 0.76404096 | J51: =J48/J46-1 -> 0.98569184 | K51: =K48/K46-1 -> 0.58625946 | L51: =L48/L46-1 -> -0.043477658 | M51: =M48/M46-1 -> -0.098635381 | ... S51: =S48/S46-1 -> 0.17597789 | U51: =U48/U46-1 -> 0.38199456 | V51: =V48/V46-1 -> 0.55562001 | W51: =W48/W46-1 -> -0.06192505 | X51: =X48/X46-1 -> 0.024100146 | Y51: =Y48/Y46-1 -> 0.17597789
...

Sheet P&L Contábil
C2: 1000000 | E2: Actual | F2: Actual | G2: Actual | I2: Actual | J2: Actual | T2: Actual | U2: Actual | V2: Actual | W2: Actual | X2: Actual | Z2: Actual | AA2: Actual | AI2: Actual | AJ2: Actual | AK2: Actual | AM2: Actual | AN2: Actual | AX2: Actual | AY2: Actual | AZ2: Actual | BA2: Actual | BB2: Actual | BD2: Actual | BE2: Actual
C3: 46143 | E3: MTD | K3: MTD | AH3: =C3 -> 46143 | AI3: YTD | AO3: YTD
C5: [ BRL M ] | E5: Base | F5: Ajuste Entre Empresas/Corp | G5: Reclass | H5: Actual Contábil | I5: Ajuste Não Recorrente | J5: Baixa Receita (Outros Anos) | K5: Actual | L5: % NR | N5: Budget | O5: % NR | P5: ∆ | Q5: ∆% | T5: HistoricoOriginal | U5: Ajuste Entre Empresas/Corp | V5: Reclass | W5: Ajuste Cloud | X5: Eliminacao Intercompany | Y5: Last Year Contábil | Z5: Ajuste Não Recorrente | AA5: Baixa Receita (Outros Anos) | AB5: Last Year | AC5: % NR | AD5: ∆ | AE5: ∆% | AI5: Base | AJ5: Ajuste Entre Empresas/Corp | AK5: Reclass | AL5: Actual Contábil | AM5: Ajuste Não Recorrente | AN5: Baixa Receita (Outros Anos) | AO5: Actual | AP5: % NR | AR5: Budget | AS5: % NR | AT5: ∆ | AU5: ∆% | AX5: HistoricoOriginal | AY5: Ajuste Entre Empresas/Corp | AZ5: Reclass | BA5: Ajuste Cloud | BB5: Eliminacao Intercompany | BC5: Last Year Contábil | BD5: Ajuste Não Recorrente | BE5: Baixa Receita (Outros Anos) | BF5: Last Year | BG5: % NR | BH5: ∆ | BI5: ∆%
B7: Gross Revenue | C7: Gross Revenue | E7: 124.22709 | F7: 0 | G7: 0 | H7: =SUM(E7:G7) -> 124.22709 | I7: 0 | J7: 2.3283064e-16 | K7: =SUM(H7:J7) -> 124.22709 | T7: 105.26204 | U7: 0 | V7: 0 | W7: 0 | X7: -1.2994338 | Y7: =SUM(T7:X7) -> 103.96261 | Z7: 0 | AA7: 0 | AB7: =SUM(Y7:AA7) -> 103.96261 | AH7: Gross Revenue | AI7: 590.92391 | AJ7: 0 | AK7: 0 | AL7: =SUM(AI7:AK7) -> 590.92391 | AM7: 0 | AN7: 3.4924597e-16 | AO7: =SUM(AL7:AN7) -> 590.92391 | AX7: 508.29344 | AY7: 0 | AZ7: 0 | BA7: 0 | BB7: -5.0745383 | BC7: =SUM(AX7:BB7) -> 503.2189 | BD7: 0 | BE7: 0 | BF7: =SUM(BC7:BE7) -> 503.2189
B8: (-) Deductions | C8: (-) Deductions | E8: -10.49242 | F8: 0 | G8: 0 | H8: =SUM(E8:G8) -> -10.49242 | I8: 0 | J8: 0 | K8: =SUM(H8:J8) -> -10.49242 | T8: -8.7770624 | U8: 0 | V8: 0 | W8: 0 | X8: 0 | Y8: =SUM(T8:X8) -> -8.7770624 | Z8: 0 | AA8: 0 | AB8: =SUM(Y8:AA8) -> -8.7770624 | AH8: (-) Deductions | AI8: -47.457135 | AJ8: 0 | AK8: 0 | AL8: =SUM(AI8:AK8) -> -47.457135 | AM8: 0 | AN8: 0 | AO8: =SUM(AL8:AN8) -> -47.457135 | AX8: -41.66283 | AY8: 0 | AZ8: 0 | BA8: 0 | BB8: 0 | BC8: =SUM(AX8:BB8) -> -41.66283 | BD8: 0 | BE8: 0 | BF8: =SUM(BC8:BE8) -> -41.66283
B9: Net Revenue | C9: Net Revenue | E9: =SUM(E7:E8) -> 113.73467 | F9: =SUM(F7:F8) -> 0 | G9: =SUM(G7:G8) -> 0 | H9: =SUM(H7:H8) -> 113.73467 | I9: =SUM(I7:I8) -> 0 | J9: =SUM(J7:J8) -> 2.3283064e-16 | K9: =SUM(K7:K8) -> 113.73467 | L9: =IFERROR(K9/K$9,0) -> 1 | N9: 113.07077 | O9: =IFERROR(N9/N$9,0) -> 1 | P9: =K9-N9 -> 0.66389816 | Q9: =IFERROR(K9/N9-1,"") -> 0.0058715277 | R9: =IF(Q9>0.05,1,IF(Q9<-0.05,-1,0)) -> 0 | T9: =SUM(T7:T8) -> 96.484978 | U9: =SUM(U7:U8) -> 0 | V9: =SUM(V7:V8) -> 0 | W9: =SUM(W7:W8) -> 0 | X9: =SUM(X7:X8) -> -1.2994338 | Y9: =SUM(T9:X9) -> 95.185544 | Z9: =SUM(Z7:Z8) -> 0 | AA9: =SUM(AA7:AA8) -> 0 | AB9: =SUM(AB7:AB8) -> 95.185544 | AC9: =IFERROR(AB9/AB$9,0) -> 1 | AD9: =$K9-AB9 -> 18.549124 | AE9: =IFERROR(K9/AB9-1,"") -> 0.19487333 | AF9: =IF(AE9>0.05,1,IF(AE9<-0.05,-1,0)) -> 1 | AH9: Net Revenue | AI9: =SUM(AI7:AI8) -> 543.46678 | AJ9: =SUM(AJ7:AJ8) -> 0 | AK9: =SUM(AK7:AK8) -> 0 | AL9: =SUM(AL7:AL8) -> 543.46678 | AM9: =SUM(AM7:AM8) -> 0 | AN9: =SUM(AN7:AN8) -> 3.4924597e-16 | AO9: =SUM(AO7:AO8) -> 543.46678 | AP9: =IFERROR(AO9/AO$9,0) -> 1 | AR9: 541.69577 | AS9: =IFERROR(AR9/AR$9,0) -> 1 | AT9: =AO9-AR9 -> 1.7710076 | AU9: =IFERROR(AO9/AR9-1,"") -> 0.0032693768 | AV9: =IF(AU9>0.05,1,IF(AU9<-0.05,-1,0)) -> 0 | AX9: =SUM(AX7:AX8) -> 466.63061 | AY9: =SUM(AY7:AY8) -> 0 | AZ9: =SUM(AZ7:AZ8) -> 0 | BA9: =SUM(BA7:BA8) -> 0 | BB9: =SUM(BB7:BB8) -> -5.0745383 | BC9: =SUM(AX9:BB9) -> 461.55607 | BD9: =SUM(BD7:BD8) -> 0 | BE9: =SUM(BE7:BE8) -> 0 | BF9: =SUM(BF7:BF8) -> 461.55607 | BG9: =IFERROR(BF9/BF$9,0) -> 1 | BH9: =$AO9-BF9 -> 81.91071 | BI9: =IFERROR(AO9/BF9-1,"") -> 0.17746644 | BJ9: =IF(BI9>0.05,1,IF(BI9<-0.05,-1,0)) -> 1
B10: (-) CoGS | C10: (-) COGS | E10: -38.090191 | F10: 0 | G10: 1.218627 | H10: =SUM(E10:G10) -> -36.871564 | I10: 0 | J10: 0 | K10: =SUM(H10:J10) -> -36.871564 | L10: =IFERROR(K10/K$9,0) -> -0.32418931 | N10: -38.26525 | O10: =IFERROR(N10/N$9,0) -> -0.33841858 | P10: =K10-N10 -> 1.3936862 | Q10: =IFERROR(K10/N10-1,"") -> -0.036421719 | T10: -33.679461 | U10: 0 | V10: 1.8643879 | W10: 0 | X10: 1.2994338 | Y10: =SUM(T10:X10) -> -30.515639 | Z10: 0 | AA10: 0 | AB10: =SUM(Y10:AA10) -> -30.515639 | AC10: =IFERROR(AB10/AB$9,0) -> -0.32059111 | AD10: =$K10-AB10 -> -6.3559243 | AE10: =IFERROR(K10/AB10-1,"") -> 0.20828416 | AH10: (-) COGS | AI10: -185.92999 | AJ10: 0 | AK10: 4.1597062 | AL10: =SUM(AI10:AK10) -> -181.77028 | AM10: 0 | AN10: 0 | AO10: =SUM(AL10:AN10) -> -181.77028 | AP10: =IFERROR(AO10/AO$9,0) -> -0.33446438 | AR10: -182.95622 | AS10: =IFERROR(AR10/AR$9,0) -> -0.33774718 | AT10: =AO10-AR10 -> 1.1859369 | AU10: =IFERROR(AO10/AR10-1,"") -> -0.0064820802 | AX10: -170.5028 | AY10: 0 | AZ10: 9.6893798 | BA10: -0.26966966 | BB10: 5.0745383 | BC10: =SUM(AX10:BB10) -> -156.00855 | BD10: 0 | BE10: 0 | BF10: =SUM(BC10:BE10) -> -156.00855 | BG10: =IFERROR(BF10/BF$9,0) -> -0.33800564 | BH10: =$AO10-BF10 -> -25.761729 | BI10: =IFERROR(AO10/BF10-1,"") -> 0.16513024
C11: = Gross Margin | E11: =SUM(E9:E10) -> 75.644477 | F11: =SUM(F9:F10) -> 0 | G11: =SUM(G9:G10) -> 1.218627 | H11: =SUM(H9:H10) -> 76.863104 | I11: =SUM(I9:I10) -> 0 | J11: =SUM(J9:J10) -> 2.3283064e-16 | K11: =SUM(K9:K10) -> 76.863104 | L11: =IFERROR(K11/K$9,0) -> 0.67581069 | N11: =N9+N10 -> 74.80552 | O11: =IFERROR(N11/N$9,0) -> 0.66158142 | P11: =K11-N11 -> 2.0575843 | Q11: =IFERROR(K11/N11-1,"") -> 0.027505782 | R11: =IF(Q11>0.05,1,IF(Q11<-0.05,-1,0)) -> 0 | T11: =SUM(T9:T10) -> 62.805517 | U11: =SUM(U9:U10) -> 0 | V11: =SUM(V9:V10) -> 1.8643879 | W11: =SUM(W9:W10) -> 0 | X11: =SUM(X9:X10) -> 0 | Y11: =SUM(Y9:Y10) -> 64.669905 | Z11: =SUM(Z9:Z10) -> 0 | AA11: =SUM(AA9:AA10) -> 0 | AB11: =SUM(AB9:AB10) -> 64.669905 | AC11: =IFERROR(AB11/AB$9,0) -> 0.67940889 | AD11: =$K11-AB11 -> 12.1932 | AE11: =IFERROR(K11/AB11-1,"") -> 0.1885452 | AF11: =IF(AE11>0.05,1,IF(AE11<-0.05,-1,0)) -> 1 | AH11: = Gross Margin | AI11: =SUM(AI9:AI10) -> 357.53679 | AJ11: =SUM(AJ9:AJ10) -> 0 | AK11: =SUM(AK9:AK10) -> 4.1597062 | AL11: =SUM(AL9:AL10) -> 361.6965 | AM11: =SUM(AM9:AM10) -> 0 | AN11: =SUM(AN9:AN10) -> 3.4924597e-16 | AO11: =SUM(AO9:AO10) -> 361.6965 | AP11: =IFERROR(AO11/AO$9,0) -> 0.66553562 | AR11: =AR9+AR10 -> 358.73955 | AS11: =IFERROR(AR11/AR$9,0) -> 0.66225282 | AT11: =AO11-AR11 -> 2.9569445 | AU11: =IFERROR(AO11/AR11-1,"") -> 0.008242594 | AV11: =IF(AU11>0.05,1,IF(AU11<-0.05,-1,0)) -> 0 | AX11: =SUM(AX9:AX10) -> 296.12781 | AY11: =SUM(AY9:AY10) -> 0 | AZ11: =SUM(AZ9:AZ10) -> 9.6893798 | BA11: =SUM(BA9:BA10) -> -0.26966966 | BB11: =SUM(BB9:BB10) -> 0 | BC11: =SUM(BC9:BC10) -> 305.54752 | BD11: =SUM(BD9:BD10) -> 0 | BE11: =SUM(BE9:BE10) -> 0 | BF11: =SUM(BF9:BF10) -> 305.54752 | BG11: =IFERROR(BF11/BF$9,0) -> 0.66199436 | BH11: =$AO11-BF11 -> 56.148981 | BI11: =IFERROR(AO11/BF11-1,"") -> 0.18376514 | BJ11: =IF(BI11>0.05,1,IF(BI11<-0.05,-1,0)) -> 1
C13: (-) Expenses | E13: =SUM(E14:E18) -> -41.175391 | F13: =SUM(F14:F18) -> -0.4807693 | G13: =SUM(G14:G18) -> -1.218627 | H13: =SUM(H14:H18) -> -42.874788 | I13: =SUM(I14:I18) -> 0.086875 | J13: =SUM(J14:J18) -> 0 | K13: =SUM(K14:K18) -> -42.787913 | L13: =IFERROR(K13/K$9,0) -> -0.37620818 | N13: =SUM(N14:N18) -> -48.034142 | O13: =IFERROR(N13/N$9,0) -> -0.42481485 | P13: =K13-N13 -> 5.2462295 | Q13: =IFERROR(K13/N13-1,"") -> -0.10921876 | T13: =SUM(T14:T18) -> -39.982952 | U13: =SUM(U14:U18) -> -0.12618796 | V13: =SUM(V14:V18) -> -1.8643879 | W13: =SUM(W14:W18) -> 0 | X13: =SUM(X14:X18) -> 0 | Y13: =SUM(Y14:Y18) -> -41.973528 | Z13: =SUM(Z14:Z18) -> 0.02257201 | AA13: =SUM(AA14:AA18) -> 0 | AB13: =SUM(AB14:AB18) -> -41.950956 | AC13: =IFERROR(AB13/AB$9,0) -> -0.44072822 | AD13: =$K13-AB13 -> -0.83695696 | AE13: =IFERROR(K13/AB13-1,"") -> 0.019950844 | AH13: (-) Expenses | AI13: =SUM(AI14:AI18) -> -230.83726 | AJ13: =SUM(AJ14:AJ18) -> 0.5436477 | AK13: =SUM(AK14:AK18) -> -4.1597062 | AL13: =SUM(AL14:AL18) -> -234.45332 | AM13: =SUM(AM14:AM18) -> 0.621875 | AN13: =SUM(AN14:AN18) -> 0 | AO13: =SUM(AO14:AO18) -> -233.83144 | AP13: =IFERROR(AO13/AO$9,0) -> -0.43025895 | AR13: =SUM(AR14:AR18) -> -232.09529 | AS13: =IFERROR(AR13/AR$9,0) -> -0.42846059 | AT13: =AO13-AR13 -> -1.7361551 | AU13: =IFERROR(AO13/AR13-1,"") -> 0.0074803546 | AX13: =SUM(AX14:AX18) -> -190.50089 | AY13: =SUM(AY14:AY18) -> -5.8884285 | AZ13: =SUM(AZ14:AZ18) -> -9.6893798 | BA13: =SUM(BA14:BA18) -> 0.26966966 | BB13: =SUM(BB14:BB18) -> 0 | BC13: =SUM(BC14:BC18) -> -205.80903 | BD13: =SUM(BD14:BD18) -> -0.55265431 | BE13: =SUM(BE14:BE18) -> 0 | BF13: =SUM(BF14:BF18) -> -206.36168 | BG13: =IFERROR(BF13/BF$9,0) -> -0.44709992 | BH13: =$AO13-BF13 -> -27.469761 | BI13: =IFERROR(AO13/BF13-1,"") -> 0.13311464
B14: (-) General & Administrative | C14: (-) General & Administrative | E14: -14.739142 | F14: -0.4652693 | G14: 2.2207367 | H14: =SUM(E14:G14) -> -12.983674 | I14: 0.086875 | J14: 0 | K14: =SUM(H14:J14) -> -12.896799 | L14: =IFERROR(K14/K$9,0) -> -0.11339374 | N14: -13.844132 | O14: =IFERROR(N14/N$9,0) -> -0.12243776 | P14: =K14-N14 -> 0.94733285 | Q14: =IFERROR(K14/N14-1,"") -> -0.068428475 | T14: -13.508229 | U14: -0.12618796 | V14: 1.063755 | W14: 0 | X14: 0 | Y14: =SUM(T14:X14) -> -12.570662 | Z14: 0.054844 | AA14: 0 | AB14: =SUM(Y14:AA14) -> -12.515818 | AC14: =IFERROR(AB14/AB$9,0) -> -0.13148864 | AD14: =$K14-AB14 -> -0.38098131 | AE14: =IFERROR(K14/AB14-1,"") -> 0.030439985 | AH14: (-) General & Administrative | AI14: -78.343974 | AJ14: 1.0550477 | AK14: 8.5753587 | AL14: =SUM(AI14:AK14) -> -68.713568 | AM14: 0.621875 | AN14: 0 | AO14: =SUM(AL14:AN14) -> -68.091693 | AP14: =IFERROR(AO14/AO$9,0) -> -0.12529136 | AR14: -67.681669 | AS14: =IFERROR(AR14/AR$9,0) -> -0.12494406 | AT14: =AO14-AR14 -> -0.41002424 | AU14: =IFERROR(AO14/AR14-1,"") -> 0.0060581284 | AX14: -64.069855 | AY14: -5.205088 | AZ14: 5.4171676 | BA14: 0 | BB14: 0 | BC14: =SUM(AX14:BB14) -> -63.857775 | BD14: 0.69235842 | BE14: 0 | BF14: =SUM(BC14:BE14) -> -63.165417 | BG14: =IFERROR(BF14/BF$9,0) -> -0.13685318 | BH14: =$AO14-BF14 -> -4.9262762 | BI14: =IFERROR(AO14/BF14-1,"") -> 0.077990084
B15: (-) Sales & Marketing | C15: (-) Sales & Marketing | E15: -13.184666 | F15: 0 | G15: -1.9152109 | H15: =SUM(E15:G15) -> -15.099876 | I15: 0 | J15: 0 | K15: =SUM(H15:J15) -> -15.099876 | L15: =IFERROR(K15/K$9,0) -> -0.13276406 | N15: -16.048389 | O15: =IFERROR(N15/N$9,0) -> -0.14193225 | P15: =K15-N15 -> 0.94851263 | Q15: =IFERROR(K15/N15-1,"") -> -0.059103292 | T15: -11.484349 | U15: 0 | V15: -2.5025589 | W15: 0 | X15: 0 | Y15: =SUM(T15:X15) -> -13.986908 | Z15: 0 | AA15: 0 | AB15: =SUM(Y15:AA15) -> -13.986908 | AC15: =IFERROR(AB15/AB$9,0) -> -0.14694362 | AD15: =$K15-AB15 -> -1.1129682 | AE15: =IFERROR(K15/AB15-1,"") -> 0.079572135 | AH15: (-) Sales & Marketing | AI15: -65.675702 | AJ15: 0 | AK15: -8.8112953 | AL15: =SUM(AI15:AK15) -> -74.486997 | AM15: 0 | AN15: 0 | AO15: =SUM(AL15:AN15) -> -74.486997 | AP15: =IFERROR(AO15/AO$9,0) -> -0.13705897 | AR15: -76.373718 | AS15: =IFERROR(AR15/AR$9,0) -> -0.14099006 | AT15: =AO15-AR15 -> 1.8867208 | AU15: =IFERROR(AO15/AR15-1,"") -> -0.024703797 | AX15: -50.426443 | AY15: -0.503801 | AZ15: -14.989079 | BA15: 0 | BB15: 0 | BC15: =SUM(AX15:BB15) -> -65.919323 | BD15: 0.078306 | BE15: 0 | BF15: =SUM(BC15:BE15) -> -65.841017 | BG15: =IFERROR(BF15/BF$9,0) -> -0.14265009 | BH15: =$AO15-BF15 -> -8.6459801 | BI15: =IFERROR(AO15/BF15-1,"") -> 0.13131602 | BK15: =AO15-K15 -> -59.387121 | BL15: =BK15/4 -> -14.84678
B16: (-) Research & Development | C16: (-) Research & Development | E16: -11.542275 | F16: -0.0155 | G16: -0.51027857 | H16: =SUM(E16:G16) -> -12.068053 | I16: 0 | J16: 0 | K16: =SUM(H16:J16) -> -12.068053 | L16: =IFERROR(K16/K$9,0) -> -0.10610708 | N16: -17.612835 | O16: =IFERROR(N16/N$9,0) -> -0.15576824 | P16: =K16-N16 -> 5.544782 | Q16: =IFERROR(K16/N16-1,"") -> -0.31481485 | T16: -14.626596 | U16: 0 | V16: -0.42558405 | W16: 0 | X16: 0 | Y16: =SUM(T16:X16) -> -15.05218 | Z16: 0 | AA16: 0 | AB16: =SUM(Y16:AA16) -> -15.05218 | AC16: =IFERROR(AB16/AB$9,0) -> -0.15813515 | AD16: =$K16-AB16 -> 2.9841272 | AE16: =IFERROR(K16/AB16-1,"") -> -0.19825216 | AH16: (-) Research & Development | AI16: -81.786056 | AJ16: -0.5114 | AK16: -2.9098954 | AL16: =SUM(AI16:AK16) -> -85.207352 | AM16: 0 | AN16: 0 | AO16: =SUM(AL16:AN16) -> -85.207352 | AP16: =IFERROR(AO16/AO$9,0) -> -0.15678484 | AR16: -85.432237 | AS16: =IFERROR(AR16/AR$9,0) -> -0.15771258 | AT16: =AO16-AR16 -> 0.22488503 | AU16: =IFERROR(AO16/AR16-1,"") -> -0.0026323206 | AX16: -74.210973 | AY16: -0.1111111 | AZ16: -0.11746809 | BA16: 0.26966966 | BB16: 0 | BC16: =SUM(AX16:BB16) -> -74.169882 | BD16: 0 | BE16: 0 | BF16: =SUM(BC16:BE16) -> -74.169882 | BG16: =IFERROR(BF16/BF$9,0) -> -0.16069528 | BH16: =$AO16-BF16 -> -11.037469 | BI16: =IFERROR(AO16/BF16-1,"") -> 0.14881336
B17: Bad Debts Provision | C17: (-) Bad Debts Provision | E17: -1.7506317 | F17: 0 | G17: 0 | H17: =SUM(E17:G17) -> -1.7506317 | I17: 0 | J17: 0 | K17: =SUM(H17:J17) -> -1.7506317 | L17: =IFERROR(K17/K$9,0) -> -0.015392243 | N17: -0.52878581 | O17: =IFERROR(N17/N$9,0) -> -0.0046765916 | P17: =K17-N17 -> -1.2218459 | Q17: =IFERROR(K17/N17-1,"") -> 2.3106631 | T17: -0.40976279 | U17: 0 | V17: 0 | W17: 0 | X17: 0 | Y17: =SUM(T17:X17) -> -0.40976279 | Z17: 0 | AA17: 0 | AB17: =SUM(Y17:AA17) -> -0.40976279 | AC17: =IFERROR(AB17/AB$9,0) -> -0.0043048847 | AD17: =$K17-AB17 -> -1.3408689 | AE17: =IFERROR(K17/AB17-1,"") -> 3.2723051 | AH17: (-) Bad Debts Provision | AI17: -4.9908547 | AJ17: 0 | AK17: 0 | AL17: =SUM(AI17:AK17) -> -4.9908547 | AM17: 0 | AN17: 0 | AO17: =SUM(AL17:AN17) -> -4.9908547 | AP17: =IFERROR(AO17/AO$9,0) -> -0.0091833667 | AR17: -2.6076659 | AS17: =IFERROR(AR17/AR$9,0) -> -0.0048138938 | AT17: =AO17-AR17 -> -2.3831888 | AU17: =IFERROR(AO17/AR17-1,"") -> 0.91391644 | AX17: -3.145584 | AY17: 0 | AZ17: 0 | BA17: 0 | BB17: 0 | BC17: =SUM(AX17:BB17) -> -3.145584 | BD17: 0 | BE17: 0 | BF17: =SUM(BC17:BE17) -> -3.145584 | BG17: =IFERROR(BF17/BF$9,0) -> -0.0068151719 | BH17: =$AO17-BF17 -> -1.8452708 | BI17: =IFERROR(AO17/BF17-1,"") -> 0.58662263
B18: Others Income and Expense | C18: (+/-) Others Income & Exp. | E18: 0.04132218 | F18: 0 | G18: -1.0138743 | H18: =SUM(E18:G18) -> -0.97255208 | I18: 0 | J18: 0 | K18: =SUM(H18:J18) -> -0.97255208 | L18: =IFERROR(K18/K$9,0) -> -0.008551061 | N18: 0 | O18: =IFERROR(N18/N$9,0) -> 0 | P18: =K18-N18 -> -0.97255208 | Q18: =IFERROR(K18/N18-1,"") | T18: 0.04598573 | U18: 0 | V18: 0 | W18: 0 | X18: 0 | Y18: =SUM(T18:X18) -> 0.04598573 | Z18: -0.03227199 | AA18: 0 | AB18: =SUM(Y18:AA18) -> 0.01371374 | AC18: =IFERROR(AB18/AB$9,0) -> 0.00014407377 | AD18: =$K18-AB18 -> -0.98626582 | AE18: =IFERROR(K18/AB18-1,"") -> -71.918078 | AH18: (+/-) Others Income & Exp. | AI18: -0.04067367 | AJ18: 0 | AK18: -1.0138743 | AL18: =SUM(AI18:AK18) -> -1.0545479 | AM18: 0 | AN18: 0 | AO18: =SUM(AL18:AN18) -> -1.0545479 | AP18: =IFERROR(AO18/AO$9,0) -> -0.0019404092 | AR18: 0 | AS18: =IFERROR(AR18/AR$9,0) -> 0 | AT18: =AO18-AR18 -> -1.0545479 | AU18: =IFERROR(AO18/AR18-1,"") | AX18: 1.3519638 | AY18: -0.06842838 | AZ18: 0 | BA18: 0 | BB18: 0 | BC18: =SUM(AX18:BB18) -> 1.2835354 | BD18: -1.3233187 | BE18: 0 | BF18: =SUM(BC18:BE18) -> -0.03978333 | BG18: =IFERROR(BF18/BF$9,0) -> -8.6193927e-05 | BH18: =$AO18-BF18 -> -1.0147646 | BI18: =IFERROR(AO18/BF18-1,"") -> 25.507282
C19: = Adjusted EBITDA | E19: =SUM(E11,E13) -> 34.469086 | F19: =SUM(F11,F13) -> -0.4807693 | G19: =SUM(G11,G13) -> 0 | H19: =SUM(H11,H13) -> 33.988317 | I19: =SUM(I11,I13) -> 0.086875 | J19: =SUM(J11,J13) -> 2.3283064e-16 | K19: =SUM(K11,K13) -> 34.075192 | L19: =IFERROR(K19/K$9,0) -> 0.29960251 | N19: =N11+N13 -> 26.771378 | O19: =IFERROR(N19/N$9,0) -> 0.23676657 | P19: =K19-N19 -> 7.3038138 | Q19: =IFERROR(K19/N19-1,"") -> 0.27282174 | R19: =IF(Q19>0.05,1,IF(Q19<-0.05,-1,0)) -> 1 | T19: =SUM(T11,T13) -> 22.822565 | U19: =SUM(U11,U13) -> -0.12618796 | V19: =SUM(V11,V13) -> 0 | W19: =SUM(W11,W13) -> 0 | X19: =SUM(X11,X13) -> 0 | Y19: =SUM(Y11,Y13) -> 22.696377 | Z19: =SUM(Z11,Z13) -> 0.02257201 | AA19: =SUM(AA11,AA13) -> 0 | AB19: =SUM(AB11,AB13) -> 22.718949 | AC19: =IFERROR(AB19/AB$9,0) -> 0.23868066 | AD19: =$K19-AB19 -> 11.356243 | AE19: =IFERROR(K19/AB19-1,"") -> 0.49985776 | AF19: =IF(AE19>0.05,1,IF(AE19<-0.05,-1,0)) -> 1 | AH19: = Adjusted EBITDA | AI19: =SUM(AI11,AI13) -> 126.69953 | AJ19: =SUM(AJ11,AJ13) -> 0.5436477 | AK19: =SUM(AK11,AK13) -> 0 | AL19: =SUM(AL11,AL13) -> 127.24318 | AM19: =SUM(AM11,AM13) -> 0.621875 | AN19: =SUM(AN11,AN13) -> 3.4924597e-16 | AO19: =SUM(AO11,AO13) -> 127.86505 | AP19: =IFERROR(AO19/AO$9,0) -> 0.23527667 | AR19: =AR11+AR13 -> 126.64426 | AS19: =IFERROR(AR19/AR$9,0) -> 0.23379223 | AT19: =AO19-AR19 -> 1.2207894 | AU19: =IFERROR(AO19/AR19-1,"") -> 0.009639516 | AV19: =IF(AU19>0.05,1,IF(AU19<-0.05,-1,0)) -> 0 | AX19: =SUM(AX11,AX13) -> 105.62692 | AY19: =SUM(AY11,AY13) -> -5.8884285 | AZ19: =SUM(AZ11,AZ13) -> 1.4210855e-14 | BA19: =SUM(BA11,BA13) -> 0 | BB19: =SUM(BB11,BB13) -> 0 | BC19: =SUM(BC11,BC13) -> 99.738487 | BD19: =SUM(BD11,BD13) -> -0.55265431 | BE19: =SUM(BE11,BE13) -> 0 | BF19: =SUM(BF11,BF13) -> 99.185833 | BG19: =IFERROR(BF19/BF$9,0) -> 0.21489444 | BH19: =$AO19-BF19 -> 28.67922 | BI19: =IFERROR(AO19/BF19-1,"") -> 0.28914633 | BJ19: =IF(BI19>0.05,1,IF(BI19<-0.05,-1,0)) -> 1
B20: BU Allocation | C20: (+/-) BU Allocation | E20: 3.4911693 | F20: 0 | G20: 0 | H20: =SUM(E20:G20) -> 3.4911693 | I20: 0 | J20: 0 | K20: =SUM(H20:J20) -> 3.4911693 | L20: =IFERROR(K20/K$9,0) -> 0.030695736 | N20: 0 | O20: =IFERROR(N20/N$9,0) -> 0 | P20: =K20-N20 -> 3.4911693 | Q20: =IFERROR(K20/N20-1,"") | T20: 0.41767093 | U20: 0 | V20: 0 | W20: 0 | X20: 0 | Y20: =SUM(T20:X20) -> 0.41767093 | Z20: 0 | AA20: 0 | AB20: =SUM(Y20:AA20) -> 0.41767093 | AC20: =IFERROR(AB20/AB$9,0) -> 0.0043879659 | AD20: =$K20-AB20 -> 3.0734984 | AE20: =IFERROR(K20/AB20-1,"") -> 7.3586602 | AH20: (+/-) BU Allocation | AI20: 16.979846 | AJ20: 0 | AK20: 0 | AL20: =SUM(AI20:AK20) -> 16.979846 | AM20: 0 | AN20: 0 | AO20: =SUM(AL20:AN20) -> 16.979846 | AP20: =IFERROR(AO20/AO$9,0) -> 0.031243576 | AR20: 0 | AS20: =IFERROR(AR20/AR$9,0) -> 0 | AT20: =AO20-AR20 -> 16.979846 | AU20: =IFERROR(AO20/AR20-1,"") | AX20: -0.88102105 | AY20: 0 | AZ20: 0 | BA20: 0 | BB20: 0 | BC20: =SUM(AX20:BB20) -> -0.88102105 | BD20: 0 | BE20: 0 | BF20: =SUM(BC20:BE20) -> -0.88102105 | BG20: =IFERROR(BF20/BF$9,0) -> -0.0019088061 | BH20: =$AO20-BF20 -> 17.860867 | BI20: =IFERROR(AO20/BF20-1,"") -> -20.272917
B21: Holding - Cost Sharing | C21: (-) Holding - Cost Sharing | E21: -6.1596697 | F21: 0 | G21: 0 | H21: =SUM(E21:G21) -> -6.1596697 | I21: 0 | J21: 0 | K21: =SUM(H21:J21) -> -6.1596697 | L21: =IFERROR(K21/K$9,0) -> -0.054158242 | N21: 0 | O21: =IFERROR(N21/N$9,0) -> 0 | P21: =K21-N21 -> -6.1596697 | Q21: =IFERROR(K21/N21-1,"") | T21: -0.67363035 | U21: 0 | V21: 0 | W21: 0 | X21: 0 | Y21: =SUM(T21:X21) -> -0.67363035 | Z21: 0 | AA21: 0 | AB21: =SUM(Y21:AA21) -> -0.67363035 | AC21: =IFERROR(AB21/AB$9,0) -> -0.0070770237 | AD21: =$K21-AB21 -> -5.4860393 | AE21: =IFERROR(K21/AB21-1,"") -> 8.1439907 | AH21: (-) Holding - Cost Sharing | AI21: -37.973932 | AJ21: 7.2759576e-18 | AK21: 0 | AL21: =SUM(AI21:AK21) -> -37.973932 | AM21: 0 | AN21: 0 | AO21: =SUM(AL21:AN21) -> -37.973932 | AP21: =IFERROR(AO21/AO$9,0) -> -0.069873511 | AR21: 0 | AS21: =IFERROR(AR21/AR$9,0) -> 0 | AT21: =AO21-AR21 -> -37.973932 | AU21: =IFERROR(AO21/AR21-1,"") | AX21: -2.314233 | AY21: 0 | AZ21: 0 | BA21: 0 | BB21: 0 | BC21: =SUM(AX21:BB21) -> -2.314233 | BD21: 0 | BE21: 0 | BF21: =SUM(BC21:BE21) -> -2.314233 | BG21: =IFERROR(BF21/BF$9,0) -> -0.0050139802 | BH21: =$AO21-BF21 -> -35.659699 | BI21: =IFERROR(AO21/BF21-1,"") -> 15.408863
B22: Shared Services | C22: (+/-) Shared Services | E22: 2.6647991 | F22: 0 | G22: 0 | H22: =SUM(E22:G22) -> 2.6647991 | I22: 0 | J22: 0 | K22: =SUM(H22:J22) -> 2.6647991 | L22: =IFERROR(K22/K$9,0) -> 0.023429963 | N22: 0 | O22: =IFERROR(N22/N$9,0) -> 0 | P22: =K22-N22 -> 2.6647991 | Q22: =IFERROR(K22/N22-1,"") | T22: 0.18852078 | U22: 0 | V22: 0 | W22: 0 | X22: 0 | Y22: =SUM(T22:X22) -> 0.18852078 | Z22: 0 | AA22: 0 | AB22: =SUM(Y22:AA22) -> 0.18852078 | AC22: =IFERROR(AB22/AB$9,0) -> 0.001980561 | AD22: =$K22-AB22 -> 2.4762783 | AE22: =IFERROR(K22/AB22-1,"") -> 13.135307 | AH22: (+/-) Shared Services | AI22: 20.976155 | AJ22: 0 | AK22: 0 | AL22: =SUM(AI22:AK22) -> 20.976155 | AM22: 0 | AN22: 0 | AO22: =SUM(AL22:AN22) -> 20.976155 | AP22: =IFERROR(AO22/AO$9,0) -> 0.038596941 | AR22: 0 | AS22: =IFERROR(AR22/AR$9,0) -> 0 | AT22: =AO22-AR22 -> 20.976155 | AU22: =IFERROR(AO22/AR22-1,"") | AX22: 3.1251551 | AY22: 0 | AZ22: 0 | BA22: 0 | BB22: 0 | BC22: =SUM(AX22:BB22) -> 3.1251551 | BD22: 0 | BE22: 0 | BF22: =SUM(BC22:BE22) -> 3.1251551 | BG22: =IFERROR(BF22/BF$9,0) -> 0.0067709111 | BH22: =$AO22-BF22 -> 17.851 | BI22: =IFERROR(AO22/BF22-1,"") -> 5.7120366
C24: Managerial EBITDA | E24: =SUM(E19:E22) -> 34.465385 | F24: =SUM(F19:F22) -> -0.4807693 | G24: =SUM(G19:G22) -> 0 | H24: =SUM(H19:H22) -> 33.984616 | I24: =SUM(I19:I22) -> 0.086875 | J24: =SUM(J19:J22) -> 2.3283064e-16 | K24: =SUM(K19:K22) -> 34.071491 | L24: =IFERROR(K24/K$9,0) -> 0.29956997 | N24: =N19+N20+N21+N22 -> 26.771378 | O24: =IFERROR(N24/N$9,0) -> 0.23676657 | P24: =K24-N24 -> 7.3001126 | Q24: =IFERROR(K24/N24-1,"") -> 0.27268348 | R24: =IF(Q24>0.05,1,IF(Q24<-0.05,-1,0)) -> 1 | T24: =SUM(T19:T22) -> 22.755126 | U24: =SUM(U19:U22) -> -0.12618796 | V24: =SUM(V19:V22) -> 0 | W24: =SUM(W19:W22) -> 0 | X24: =SUM(X19:X22) -> 0 | Y24: =SUM(Y19:Y22) -> 22.628938 | Z24: =SUM(Z19:Z22) -> 0.02257201 | AA24: =SUM(AA19:AA22) -> 0 | AB24: =SUM(AB19:AB22) -> 22.65151 | AC24: =IFERROR(AB24/AB$9,0) -> 0.23797217 | AD24: =$K24-AB24 -> 11.41998 | AE24: =IFERROR(K24/AB24-1,"") -> 0.50415977 | AF24: =IF(AE24>0.05,1,IF(AE24<-0.05,-1,0)) -> 1 | AH24: Managerial EBITDA | AI24: =SUM(AI19:AI22) -> 126.6816 | AJ24: =SUM(AJ19:AJ22) -> 0.5436477 | AK24: =SUM(AK19:AK22) -> 0 | AL24: =SUM(AL19:AL22) -> 127.22525 | AM24: =SUM(AM19:AM22) -> 0.621875 | AN24: =SUM(AN19:AN22) -> 3.4924597e-16 | AO24: =SUM(AO19:AO22) -> 127.84712 | AP24: =IFERROR(AO24/AO$9,0) -> 0.23524367 | AR24: =AR19+AR20+AR21+AR22 -> 126.64426 | AS24: =IFERROR(AR24/AR$9,0) -> 0.23379223 | AT24: =AO24-AR24 -> 1.2028584 | AU24: =IFERROR(AO24/AR24-1,"") -> 0.0094979306 | AV24: =IF(AU24>0.05,1,IF(AU24<-0.05,-1,0)) -> 0 | AX24: =SUM(AX19:AX22) -> 105.55682 | AY24: =SUM(AY19:AY22) -> -5.8884285 | AZ24: =SUM(AZ19:AZ22) -> 1.4210855e-14 | BA24: =SUM(BA19:BA22) -> 0 | BB24: =SUM(BB19:BB22) -> 0 | BC24: =SUM(BC19:BC22) -> 99.668388 | BD24: =SUM(BD19:BD22) -> -0.55265431 | BE24: =SUM(BE19:BE22) -> 0 | BF24: =SUM(BF19:BF22) -> 99.115734 | BG24: =IFERROR(BF24/BF$9,0) -> 0.21474256 | BH24: =$AO24-BF24 -> 28.731388 | BI24: =IFERROR(AO24/BF24-1,"") -> 0.28987717 | BJ24: =IF(BI24>0.05,1,IF(BI24<-0.05,-1,0)) -> 1
B25: Adjustments to EBITDA | C25: (+/-) Non-recurring | E25: -0.4807693 | F25: 0.4807693 | G25: 0 | H25: =SUM(E25:G25) -> 0 | I25: -0.086875 | J25: 0 | K25: =SUM(H25:J25) -> -0.086875 | L25: =IFERROR(K25/K$9,0) -> -0.00076383922 | N25: -0.088 | O25: =IFERROR(N25/N$9,0) -> -0.00077827364 | P25: =K25-N25 -> 0.001125 | Q25: =IFERROR(K25/N25-1,"") -> -0.012784091 | T25: -0.12618796 | U25: 0.12618796 | V25: 0 | W25: 0 | X25: 0 | Y25: =SUM(T25:X25) -> 0 | Z25: -0.02257201 | AA25: 0 | AB25: =SUM(Y25:AA25) -> -0.02257201 | AC25: =IFERROR(AB25/AB$9,0) -> -0.00023713695 | AD25: =$K25-AB25 -> -0.06430299 | AE25: =IFERROR(K25/AB25-1,"") -> 2.8487933 | AH25: (+/-) Non-recurring | AI25: 0.54338492 | AJ25: -0.5436477 | AK25: 0 | AL25: =SUM(AI25:AK25) -> -0.00026278 | AM25: -0.621875 | AN25: 0 | AO25: =SUM(AL25:AN25) -> -0.62213778 | AP25: =IFERROR(AO25/AO$9,0) -> -0.0011447577 | AR25: -0.69 | AS25: =IFERROR(AR25/AR$9,0) -> -0.0012737777 | AT25: =AO25-AR25 -> 0.06786222 | AU25: =IFERROR(AO25/AR25-1,"") -> -0.098351043 | AX25: -5.8884285 | AY25: 5.8884285 | AZ25: 0 | BA25: 0 | BB25: 0 | BC25: =SUM(AX25:BB25) -> 0 | BD25: 0.55265431 | BE25: 0 | BF25: =SUM(BC25:BE25) -> 0.55265431 | BG25: =IFERROR(BF25/BF$9,0) -> 0.001197372 | BH25: =$AO25-BF25 -> -1.1747921 | BI25: =IFERROR(AO25/BF25-1,"") -> -2.1257268
C26: = EBITDA | E26: =SUM(E24:E25) -> 33.984616 | F26: =SUM(F24:F25) -> 0 | G26: =SUM(G24:G25) -> 0 | H26: =SUM(H24:H25) -> 33.984616 | I26: =SUM(I24:I25) -> 0 | J26: =SUM(J24:J25) -> 2.3283064e-16 | K26: =SUM(K24:K25) -> 33.984616 | L26: =IFERROR(K26/K$9,0) -> 0.29880613 | N26: =N24+N25 -> 26.683378 | O26: =IFERROR(N26/N$9,0) -> 0.23598829 | P26: =K26-N26 -> 7.3012376 | Q26: =IFERROR(K26/N26-1,"") -> 0.27362494 | R26: =IF(Q26>0.05,1,IF(Q26<-0.05,-1,0)) -> 1 | T26: =SUM(T24:T25) -> 22.628938 | U26: =SUM(U24:U25) -> 0 | V26: =SUM(V24:V25) -> 0 | W26: =SUM(W24:W25) -> 0 | X26: =SUM(X24:X25) -> 0 | Y26: =SUM(Y24:Y25) -> 22.628938 | Z26: =SUM(Z24:Z25) -> 0 | AA26: =SUM(AA24:AA25) -> 0 | AB26: =SUM(AB24:AB25) -> 22.628938 | AC26: =IFERROR(AB26/AB$9,0) -> 0.23773503 | AD26: =$K26-AB26 -> 11.355677 | AE26: =IFERROR(K26/AB26-1,"") -> 0.50182104 | AF26: =IF(AE26>0.05,1,IF(AE26<-0.05,-1,0)) -> 1 | AH26: = EBITDA | AI26: =SUM(AI24:AI25) -> 127.22498 | AJ26: =SUM(AJ24:AJ25) -> 0 | AK26: =SUM(AK24:AK25) -> 0 | AL26: =SUM(AL24:AL25) -> 127.22498 | AM26: =SUM(AM24:AM25) -> 0 | AN26: =SUM(AN24:AN25) -> 3.4924597e-16 | AO26: =SUM(AO24:AO25) -> 127.22498 | AP26: =IFERROR(AO26/AO$9,0) -> 0.23409892 | AR26: =AR24+AR25 -> 125.95426 | AS26: =IFERROR(AR26/AR$9,0) -> 0.23251845 | AT26: =AO26-AR26 -> 1.2707207 | AU26: =IFERROR(AO26/AR26-1,"") -> 0.010088747 | AV26: =IF(AU26>0.05,1,IF(AU26<-0.05,-1,0)) -> 0 | AX26: =SUM(AX24:AX25) -> 99.668388 | AY26: =SUM(AY24:AY25) -> 0 | AZ26: =SUM(AZ24:AZ25) -> 1.4210855e-14 | BA26: =SUM(BA24:BA25) -> 0 | BB26: =SUM(BB24:BB25) -> 0 | BC26: =SUM(BC24:BC25) -> 99.668388 | BD26: =SUM(BD24:BD25) -> 0 | BE26: =SUM(BE24:BE25) -> 0 | BF26: =SUM(BF24:BF25) -> 99.668388 | BG26: =IFERROR(BF26/BF$9,0) -> 0.21593994 | BH26: =$AO26-BF26 -> 27.556596 | BI26: =IFERROR(AO26/BF26-1,"") -> 0.27648281 | BJ26: =IF(BI26>0.05,1,IF(BI26<-0.05,-1,0)) -> 1
C27: (-) D&A | E27: =SUM(E28:E29) -> -8.7318616 | F27: =SUM(F28:F29) -> 0 | G27: =SUM(G28:G29) -> 0 | H27: =SUM(H28:H29) -> -8.7318616 | I27: =SUM(I28:I29) -> 0 | J27: =SUM(J28:J29) -> 0 | K27: =SUM(K28:K29) -> -8.7318616 | L27: =IFERROR(K27/K$9,0) -> -0.076773966 | N27: =SUM(N28:N29) -> -8.8445773 | O27: =IFERROR(N27/N$9,0) -> -0.078221607 | P27: =K27-N27 -> 0.11271576 | Q27: =IFERROR(K27/N27-1,"") -> -0.012744053 | T27: =SUM(T28:T29) -> -7.6700771 | U27: =SUM(U28:U29) -> 0 | V27: =SUM(V28:V29) -> 0 | W27: =SUM(W28:W29) -> 0 | X27: =SUM(X28:X29) -> 0 | Y27: =SUM(Y28:Y29) -> -7.6700771 | Z27: =SUM(Z28:Z29) -> 0 | AA27: =SUM(AA28:AA29) -> 0 | AB27: =SUM(AB28:AB29) -> -7.6700771 | AC27: =IFERROR(AB27/AB$9,0) -> -0.080580273 | AD27: =$K27-AB27 -> -1.0617844 | AE27: =IFERROR(K27/AB27-1,"") -> 0.13843204 | AF27: =IF(AE27>0.05,1,IF(AE27<-0.05,-1,0)) -> 1 | AI27: =SUM(AI28:AI29) -> -43.955698 | AJ27: =SUM(AJ28:AJ29) -> 0 | AK27: =SUM(AK28:AK29) -> 0 | AL27: =SUM(AL28:AL29) -> -43.955698 | AM27: =SUM(AM28:AM29) -> 0 | AN27: =SUM(AN28:AN29) -> 0 | AO27: =SUM(AO28:AO29) -> -43.955698 | AP27: =IFERROR(AO27/AO$9,0) -> -0.080880193 | AR27: =SUM(AR28:AR29) -> -45.689141 | AS27: =IFERROR(AR27/AR$9,0) -> -0.084344651 | AT27: =AO27-AR27 -> 1.733443 | AU27: =IFERROR(AO27/AR27-1,"") -> -0.037939934 | AV27: =IF(AU27>0.05,1,IF(AU27<-0.05,-1,0)) -> 0 | AX27: =SUM(AX28:AX29) -> -40.793179 | AY27: =SUM(AY28:AY29) -> 0 | AZ27: =SUM(AZ28:AZ29) -> 0 | BA27: =SUM(BA28:BA29) -> 0 | BB27: =SUM(BB28:BB29) -> 0 | BC27: =SUM(BC28:BC29) -> -40.793179 | BD27: =SUM(BD28:BD29) -> 0 | BE27: =SUM(BE28:BE29) -> 0 | BF27: =SUM(BF28:BF29) -> -40.793179 | BG27: =IFERROR(BF27/BF$9,0) -> -0.088381849 | BH27: =$AO27-BF27 -> -3.162519 | BI27: =IFERROR(AO27/BF27-1,"") -> 0.077525683 | BJ27: =IF(BI27>0.05,1,IF(BI27<-0.05,-1,0)) -> 1
B28: D&A | C28: (-) D&A Operating Assests | E28: -3.9002693 | F28: 0 | G28: 0 | H28: =SUM(E28:G28) -> -3.9002693 | I28: 0 | J28: 0 | K28: =SUM(H28:J28) -> -3.9002693 | L28: =IFERROR(K28/K$9,0) -> -0.034292704 | N28: -3.8564283 | O28: =IFERROR(N28/N$9,0) -> -0.034106324 | P28: =K28-N28 -> -0.043840937 | Q28: =IFERROR(K28/N28-1,"") -> 0.011368275 | T28: -2.503726 | U28: 0 | V28: 0 | W28: 0 | X28: 0 | Y28: =SUM(T28:X28) -> -2.503726 | Z28: 0 | AA28: 0 | AB28: =SUM(Y28:AA28) -> -2.503726 | AC28: =IFERROR(AB28/AB$9,0) -> -0.026303637 | AD28: =$K28-AB28 -> -1.3965433 | AE28: =IFERROR(K28/AB28-1,"") -> 0.55778598 | AH28: (-) D&A | AI28: -19.652629 | AJ28: 0 | AK28: 0 | AL28: =SUM(AI28:AK28) -> -19.652629 | AM28: 0 | AN28: 0 | AO28: =SUM(AL28:AN28) -> -19.652629 | AP28: =IFERROR(AO28/AO$9,0) -> -0.036161602 | AR28: -19.727686 | AS28: =IFERROR(AR28/AR$9,0) -> -0.036418387 | AT28: =AO28-AR28 -> 0.075056793 | AU28: =IFERROR(AO28/AR28-1,"") -> -0.0038046425 | AX28: -15.198728 | AY28: 0 | AZ28: 0 | BA28: 0 | BB28: 0 | BC28: =SUM(AX28:BB28) -> -15.198728 | BD28: 0 | BE28: 0 | BF28: =SUM(BC28:BE28) -> -15.198728 | BG28: =IFERROR(BF28/BF$9,0) -> -0.03292932 | BH28: =$AO28-BF28 -> -4.4539018 | BI28: =IFERROR(AO28/BF28-1,"") -> 0.29304439
B29: M&A Amortization | C29: (-) M&A Amortization | E29: -4.8315923 | F29: 0 | G29: 0 | H29: =SUM(E29:G29) -> -4.8315923 | I29: 0 | J29: 0 | K29: =SUM(H29:J29) -> -4.8315923 | L29: =IFERROR(K29/K$9,0) -> -0.042481263 | N29: -4.988149 | O29: =IFERROR(N29/N$9,0) -> -0.044115283 | P29: =K29-N29 -> 0.1565567 | Q29: =IFERROR(K29/N29-1,"") -> -0.03138573 | T29: -5.1663511 | U29: 0 | V29: 0 | W29: 0 | X29: 0 | Y29: =SUM(T29:X29) -> -5.1663511 | Z29: 0 | AA29: 0 | AB29: =SUM(Y29:AA29) -> -5.1663511 | AC29: =IFERROR(AB29/AB$9,0) -> -0.054276636 | AD29: =$K29-AB29 -> 0.33475884 | AE29: =IFERROR(K29/AB29-1,"") -> -0.064795991 | AH29: (-) M&A Amortization | AI29: -24.303068 | AJ29: 0 | AK29: 0 | AL29: =SUM(AI29:AK29) -> -24.303068 | AM29: 0 | AN29: 0 | AO29: =SUM(AL29:AN29) -> -24.303068 | AP29: =IFERROR(AO29/AO$9,0) -> -0.044718591 | AR29: -25.961455 | AS29: =IFERROR(AR29/AR$9,0) -> -0.047926264 | AT29: =AO29-AR29 -> 1.6583862 | AU29: =IFERROR(AO29/AR29-1,"") -> -0.063878785 | AX29: -25.594451 | AY29: 0 | AZ29: 0 | BA29: 0 | BB29: 0 | BC29: =SUM(AX29:BB29) -> -25.594451 | BD29: 0 | BE29: 0 | BF29: =SUM(BC29:BE29) -> -25.594451 | BG29: =IFERROR(BF29/BF$9,0) -> -0.055452529 | BH29: =$AO29-BF29 -> 1.2913828 | BI29: =IFERROR(AO29/BF29-1,"") -> -0.050455576
B30: Financial Results | C30: (+/-) Financial Results | E30: -0.74368261 | F30: 0 | G30: 0 | H30: =SUM(E30:G30) -> -0.74368261 | I30: 0 | J30: 0 | K30: =SUM(H30:J30) -> -0.74368261 | L30: =IFERROR(K30/K$9,0) -> -0.0065387504 | N30: -1.4781771 | O30: =IFERROR(N30/N$9,0) -> -0.013073026 | P30: =K30-N30 -> 0.73449446 | Q30: =IFERROR(K30/N30-1,"") -> -0.49689207 | T30: -3.2063321 | U30: 0 | V30: 0 | W30: 0 | X30: 0 | Y30: =SUM(T30:X30) -> -3.2063321 | Z30: 0 | AA30: 0 | AB30: =SUM(Y30:AA30) -> -3.2063321 | AC30: =IFERROR(AB30/AB$9,0) -> -0.033685074 | AD30: =$K30-AB30 -> 2.4626495 | AE30: =IFERROR(K30/AB30-1,"") -> -0.76805815 | AH30: (+/-) Financial Results | AI30: -5.262409 | AJ30: 0 | AK30: 0 | AL30: =SUM(AI30:AK30) -> -5.262409 | AM30: 0 | AN30: 0 | AO30: =SUM(AL30:AN30) -> -5.262409 | AP30: =IFERROR(AO30/AO$9,0) -> -0.0096830371 | AR30: -8.0803088 | AS30: =IFERROR(AR30/AR$9,0) -> -0.014916692 | AT30: =AO30-AR30 -> 2.8178998 | AU30: =IFERROR(AO30/AR30-1,"") -> -0.34873664 | AX30: -10.368245 | AY30: 0 | AZ30: 0 | BA30: 0 | BB30: 0 | BC30: =SUM(AX30:BB30) -> -10.368245 | BD30: 0 | BE30: 0 | BF30: =SUM(BC30:BE30) -> -10.368245 | BG30: =IFERROR(BF30/BF$9,0) -> -0.022463673 | BH30: =$AO30-BF30 -> 5.1058358 | BI30: =IFERROR(AO30/BF30-1,"") -> -0.49244939
C31: (+) Financial Revenue | K31: 2.7418117 | L31: =IFERROR(K31/K$9,0) -> 0.024107088 | N31: 1.1928444 | O31: =IFERROR(N31/N$9,0) -> 0.010549538 | P31: =K31-N31 -> 1.5489673 | Q31: =IFERROR(K31/N31-1,"") -> 1.2985493 | AB31: 0.99911402 | AC31: =IFERROR(AB31/AB$9,0) -> 0.010496489 | AD31: =$K31-AB31 -> 1.7426977 | AE31: =IFERROR(K31/AB31-1,"") -> 1.744243 | AO31: 17.139972 | AP31: =IFERROR(AO31/AO$9,0) -> 0.031538214 | AR31: 6.0266249 | AS31: =IFERROR(AR31/AR$9,0) -> 0.011125479 | AT31: =AO31-AR31 -> 11.113347 | AU31: =IFERROR(AO31/AR31-1,"") -> 1.8440415 | BF31: 9.9846335 | BG31: =IFERROR(BF31/BF$9,0) -> 0.021632547 | BH31: =$AO31-BF31 -> 7.155338 | BI31: =IFERROR(AO31/BF31-1,"") -> 0.71663502
C32: (-) Financial Expenses | K32: -3.4471245 | L32: =IFERROR(K32/K$9,0) -> -0.030308477 | N32: -2.6710215 | O32: =IFERROR(N32/N$9,0) -> -0.023622564 | P32: =K32-N32 -> -0.77610307 | Q32: =IFERROR(K32/N32-1,"") -> 0.29056415 | AB32: -4.2054469 | AC32: =IFERROR(AB32/AB$9,0) -> -0.044181571 | AD32: =$K32-AB32 -> 0.75832236 | AE32: =IFERROR(K32/AB32-1,"") -> -0.18031909 | AO32: -22.36428 | AP32: =IFERROR(AO32/AO$9,0) -> -0.041151145 | AR32: -14.106934 | AS32: =IFERROR(AR32/AR$9,0) -> -0.026042171 | AT32: =AO32-AR32 -> -8.2573468 | AU32: =IFERROR(AO32/AR32-1,"") -> 0.58533959 | BF32: -20.368833 | BG32: =IFERROR(BF32/BF$9,0) -> -0.044130788 | BH32: =$AO32-BF32 -> -1.9954473 | BI32: =IFERROR(AO32/BF32-1,"") -> 0.097965713
C33: (-) Income Tax | E33: =SUM(E34:E35) -> -5.7406935 | F33: =SUM(F34:F35) -> 0 | G33: =SUM(G34:G35) -> 0 | H33: =SUM(H34:H35) -> -5.7406935 | I33: =SUM(I34:I35) -> 0 | J33: =SUM(J34:J35) -> 0 | K33: =SUM(K34:K35) -> -5.7406935 | L33: =IFERROR(K33/K$9,0) -> -0.050474439 | N33: =SUM(N34:N35) -> -7.4642437 | O33: =IFERROR(N33/N$9,0) -> -0.066013911 | P33: =K33-N33 -> 1.7235502 | Q33: =IFERROR(K33/N33-1,"") -> -0.23090755 | T33: =SUM(T34:T35) -> -14.041346 | U33: =SUM(U34:U35) -> 0 | V33: =SUM(V34:V35) -> 0 | W33: =SUM(W34:W35) -> 0 | X33: =SUM(X34:X35) -> 0 | Y33: =SUM(Y34:Y35) -> -14.041346 | Z33: =SUM(Z34:Z35) -> 0 | AA33: =SUM(AA34:AA35) -> 0 | AB33: =SUM(AB34:AB35) -> -14.041346 | AC33: =IFERROR(AB33/AB$9,0) -> -0.14751553 | AD33: =$K33-AB33 -> 8.3006529 | AE33: =IFERROR(K33/AB33-1,"") -> -0.5911579 | AI33: =SUM(AI34:AI35) -> -28.282652 | AJ33: =SUM(AJ34:AJ35) -> 0 | AK33: =SUM(AK34:AK35) -> 0 | AL33: =SUM(AL34:AL35) -> -28.282652 | AM33: =SUM(AM34:AM35) -> 0 | AN33: =SUM(AN34:AN35) -> 0 | AO33: =SUM(AO34:AO35) -> -28.282652 | AP33: =IFERROR(AO33/AO$9,0) -> -0.05204118 | AR33: =SUM(AR34:AR35) -> -35.778353 | AS33: =IFERROR(AR33/AR$9,0) -> -0.066048796 | AT33: =AO33-AR33 -> 7.495701 | AU33: =IFERROR(AO33/AR33-1,"") -> -0.2095038 | AX33: =SUM(AX34:AX35) -> -23.010915 | AY33: =SUM(AY34:AY35) -> 0 | AZ33: =SUM(AZ34:AZ35) -> 0 | BA33: =SUM(BA34:BA35) -> 0 | BB33: =SUM(BB34:BB35) -> 0 | BC33: =SUM(BC34:BC35) -> -23.010915 | BD33: =SUM(BD34:BD35) -> 0 | BE33: =SUM(BE34:BE35) -> 0 | BF33: =SUM(BF34:BF35) -> -23.010915 | BG33: =IFERROR(BF33/BF$9,0) -> -0.04985508 | BH33: =$AO33-BF33 -> -5.2717377 | BI33: =IFERROR(AO33/BF33-1,"") -> 0.22909727
B34: Income Tax | C34: (-) Current | E34: -5.1142733 | F34: 0 | G34: 0 | H34: =SUM(E34:G34) -> -5.1142733 | I34: 0 | J34: 0 | K34: =SUM(H34:J34) -> -5.1142733 | L34: =IFERROR(K34/K$9,0) -> -0.044966706 | N34: -5.4016825 | O34: =IFERROR(N34/N$9,0) -> -0.04777258 | P34: =K34-N34 -> 0.28740912 | Q34: =IFERROR(K34/N34-1,"") -> -0.053207334 | T34: -5.7813332 | U34: 0 | V34: 0 | W34: 0 | X34: 0 | Y34: =SUM(T34:X34) -> -5.7813332 | Z34: 0 | AA34: 0 | AB34: =SUM(Y34:AA34) -> -5.7813332 | AC34: =IFERROR(AB34/AB$9,0) -> -0.060737513 | AD34: =$K34-AB34 -> 0.66705987 | AE34: =IFERROR(K34/AB34-1,"") -> -0.11538167 | AH34: (-) Income Tax | AI34: -17.499858 | AJ34: 0 | AK34: 0 | AL34: =SUM(AI34:AK34) -> -17.499858 | AM34: 0 | AN34: 0 | AO34: =SUM(AL34:AN34) -> -17.499858 | AP34: =IFERROR(AO34/AO$9,0) -> -0.032200419 | AR34: -25.48615 | AS34: =IFERROR(AR34/AR$9,0) -> -0.047048826 | AT34: =AO34-AR34 -> 7.9862921 | AU34: =IFERROR(AO34/AR34-1,"") -> -0.31335812 | AX34: -17.445239 | AY34: 0 | AZ34: 0 | BA34: 0 | BB34: 0 | BC34: =SUM(AX34:BB34) -> -17.445239 | BD34: 0 | BE34: 0 | BF34: =SUM(BC34:BE34) -> -17.445239 | BG34: =IFERROR(BF34/BF$9,0) -> -0.037796577 | BH34: =$AO34-BF34 -> -0.054618422 | BI34: =IFERROR(AO34/BF34-1,"") -> 0.0031308497
